# TODO: Consider adding connection pooling configuration
"""
"""
T = TypeVar("T")
R = TypeVar("R")
E = TypeVar("E", bound=Exception)
F = TypeVar("F", bound=Callable[..., Any])
AsyncF = TypeVar("AsyncF", bound=Callable[..., Any])

# Configure logging
logger = logging.getLogger(__name__)

class ErrorSeverity(enum.Enum):
    """Error severity levels for standardized error handling."""
    DEBUG = "debug"
    INFO = "info"
    WARNING = "warning"
    ERROR = "error"
    CRITICAL = "critical"

class BaseError(Exception):
    """Base class for all custom exceptions in the codebase."""
        """
        """
        """
        """
            "message": self.message,
            "severity": self.severity.value,
            "details": self.details,
        }

        if self.cause:
            result["cause"] = str(self.cause)

        return result

    def __str__(self) -> str:
        """
        """
            return f"{self.message} (caused by: {type(self.cause).__name__}: {str(self.cause)})"
        return self.message

def handle_exception(
    target_error: Optional[Type[BaseError]] = None,
    logger: Optional[logging.Logger] = None,
    default_message: Optional[str] = None,
) -> Callable[[F], F]:
    """
    """
            default_message = f"Error in {func.__name__}"

        @functools.wraps(func)
        def wrapper(*args: Any, **kwargs: Any) -> Any:
            try:

                pass
                return func(*args, **kwargs)
            except Exception:

                pass
                # Log the error with appropriate severity
                log_level = {
                    ErrorSeverity.DEBUG: logger.debug,
                    ErrorSeverity.INFO: logger.info,
                    ErrorSeverity.WARNING: logger.warning,
                    ErrorSeverity.ERROR: logger.error,
                    ErrorSeverity.CRITICAL: logger.critical,
                }[e.severity]

                log_level(f"{type(e).__name__}: {e.message}")
                if e.details:
                if e.cause:

                # Re-raise the error
                raise
            except Exception:

                pass
                # Log the unexpected error
                logger.error(f"Unexpected error in {func.__name__}: {str(e)}")

                # Wrap the error in a BaseError if target_error is provided
                if target_error:
                    error_message = default_message
                    raise target_error(
                        message=error_message,
                        severity=ErrorSeverity.ERROR,
                        details={"original_error": str(e)},
                        cause=e,
                    ) from e
                else:
                    # Re-raise the original error if no target_error is specified
                    raise

        return cast(F, wrapper)

    return decorator

def handle_async_exception(
    target_error: Optional[Type[BaseError]] = None,
    logger: Optional[logging.Logger] = None,
    default_message: Optional[str] = None,
) -> Callable[[AsyncF], AsyncF]:
    """
    """
            default_message = f"Error in {func.__name__}"

        @functools.wraps(func)
        async def wrapper(*args: Any, **kwargs: Any) -> Any:
            try:

                pass
                return await func(*args, **kwargs)
            except Exception:

                pass
                # Log the error with appropriate severity
                log_level = {
                    ErrorSeverity.DEBUG: logger.debug,
                    ErrorSeverity.INFO: logger.info,
                    ErrorSeverity.WARNING: logger.warning,
                    ErrorSeverity.ERROR: logger.error,
                    ErrorSeverity.CRITICAL: logger.critical,
                }[e.severity]

                log_level(f"{type(e).__name__}: {e.message}")
                if e.details:
                if e.cause:

                # Re-raise the error
                raise
            except Exception:

                pass
                # Log the unexpected error
                logger.error(f"Unexpected error in {func.__name__}: {str(e)}")

                # Wrap the error in a BaseError if target_error is provided
                if target_error:
                    error_message = default_message
                    raise target_error(
                        message=error_message,
                        severity=ErrorSeverity.ERROR,
                        details={"original_error": str(e)},
                        cause=e,
                    ) from e
                else:
                    # Re-raise the original error if no target_error is specified
                    raise

        return cast(AsyncF, wrapper)

    return decorator

@contextmanager
def error_context(
    target_error: Type[BaseError],
    message: str,
    logger: Optional[logging.Logger] = None,
    details: Optional[Dict[str, Any]] = None,
):
    """
        with error_context(DatabaseError, "Error updating user record", details={"user_id": 123}):
            db.update_user(user_id=123, data={"status": "active"})
    """
            module_name = frame.f_back.f_globals.get("__name__", "")
            logger = logging.getLogger(module_name)
        else:
            logger = logging.getLogger(__name__)

    try:


        pass
        yield
    except Exception:

        pass
        # Log the error with appropriate severity
        log_level = {
            ErrorSeverity.DEBUG: logger.debug,
            ErrorSeverity.INFO: logger.info,
            ErrorSeverity.WARNING: logger.warning,
            ErrorSeverity.ERROR: logger.error,
            ErrorSeverity.CRITICAL: logger.critical,
        }[e.severity]

        log_level(f"{type(e).__name__}: {e.message}")
        if e.details:
        if e.cause:

        # Re-raise the error
        raise
    except Exception:

        pass
        # Log the unexpected error
        logger.error(f"Error in context '{message}': {str(e)}")

        # Wrap the error in the target_error
        raise target_error(
            message=message,
            severity=ErrorSeverity.ERROR,
            details=details or {"original_error": str(e)},
            cause=e,
        ) from e

def safe_execute(
    func: Callable[..., T],
    *args: Any,
    default: T = None,
    log_errors: bool = True,
    logger: Optional[logging.Logger] = None,
    **kwargs: Any,
) -> T:
    """
    """
            logger.error(f"Error executing {func.__name__}: {str(e)}")
        return default

async def safe_execute_async(
    func: Callable[..., Any],
    *args: Any,
    default: Any = None,
    log_errors: bool = True,
    logger: Optional[logging.Logger] = None,
    **kwargs: Any,
) -> Any:
    """
    """
            logger.error(f"Error executing {func.__name__}: {str(e)}")
        return default

def with_retry(
    max_attempts: int = 3,
    initial_backoff: float = 1.0,
    max_backoff: float = 30.0,
    backoff_multiplier: float = 2.0,
    jitter: float = 0.1,
    retryable_errors: Optional[tuple[Type[Exception], ...]] = None,
) -> Callable[[F], F]:
    """
    """
                            f"All {max_attempts} attempts failed for {func.__name__}",
                            exc_info=True,
                        )
                        raise

                    # Calculate backoff with jitter
                    backoff = min(
                        initial_backoff * (backoff_multiplier ** (attempt - 1)),
                        max_backoff,
                    )
                    # Add jitter
                    actual_backoff = backoff * (1 + random.uniform(-jitter, jitter))

                    logger.warning(
                        f"Attempt {attempt} failed for {func.__name__}, " f"retrying in {actual_backoff:.2f}s: {str(e)}"
                    )

                    # Wait before retrying
                    await asyncio.sleep(actual_backoff)

            # This should never be reached, but for type safety
            if last_exception:
                raise last_exception
            return None

        return cast(F, wrapper)

    return decorator

async def with_async_retry(
    max_attempts: int = 3,
    initial_backoff: float = 1.0,
    max_backoff: float = 30.0,
    backoff_multiplier: float = 2.0,
    jitter: float = 0.1,
    retryable_errors: Optional[tuple[Type[Exception], ...]] = None,
) -> Callable[[AsyncF], AsyncF]:
    """
    """
                            f"All {max_attempts} attempts failed for {func.__name__}",
                            exc_info=True,
                        )
                        raise

                    # Calculate backoff with jitter
                    backoff = min(
                        initial_backoff * (backoff_multiplier ** (attempt - 1)),
                        max_backoff,
                    )
                    # Add jitter
                    actual_backoff = backoff * (1 + random.uniform(-jitter, jitter))

                    logger.warning(
                        f"Attempt {attempt} failed for {func.__name__}, " f"retrying in {actual_backoff:.2f}s: {str(e)}"
                    )

                    # Wait before retrying
                    await asyncio.sleep(actual_backoff)

            # This should never be reached, but for type safety
            if last_exception:
                raise last_exception
            return None

        return cast(AsyncF, wrapper)

    return decorator

def map_exception(
    exception: Exception,
    target_error: Type[BaseError],
    message: Optional[str] = None,
) -> BaseError:
    """
            raise map_exception(e, ExternalServiceError, "Failed to fetch data")
    """
    """Error related to configuration issues."""
    """Error related to data processing."""
    """Error related to network operations."""
    """Error related to database operations."""
    """Error related to validation failures."""
    """Error related to authentication failures."""
    """Error related to authorization failures."""
    """Error raised when a resource cannot be found."""
    """Example of using the error handling decorator."""
        if not path.endswith(".json"):
            raise ValueError("Config file must be JSON")
        return {"key": "value"}

    try:


        pass
        load_config("config.yaml")  # This will raise ConfigError
    except Exception:

        pass
        print(f"Caught error: {e}")

def example_with_context_manager() -> None:
    """Example of using the error context manager."""
        if "id" not in item:
            raise KeyError("Item must have an ID")

    try:


        pass
        with error_context(DataProcessingError, "Error processing item", details={"item_id": 123}):
            process_item({})  # This will raise DataProcessingError
    except Exception:

        pass
        print(f"Caught error: {e}")

def example_with_safe_execute() -> None:
    """Example of using safe execution."""
    result = safe_execute(parse_json, "{invalid: json}", default={})
    print(f"Result: {result}")

async def example_with_retry() -> None:
    """Example of using retry logic."""
            raise ConnectionError("Connection failed")

        return {"data": "success"}

    try:


        pass
        result = fetch_data("https://example.com/api")
        print(f"Result after {attempt_count} attempts: {result}")
    except Exception:

        pass
        print(f"Failed after {attempt_count} attempts: {e}")

if __name__ == "__main__":
    # Configure logging
    logging.basicConfig(
        level=logging.DEBUG,
        format="%(asctime)s - %(name)s - %(levelname)s - %(message)s",
    )

    # Run the examples
    example_with_decorator()
    example_with_context_manager()
    example_with_safe_execute()

    # Run the async example using asyncio
    # import asyncio  # Removed redundant unused import

    asyncio.run(example_with_retry())
