"""
"""
T = TypeVar("T")
F = TypeVar("F", bound=Callable[..., Any])

# Configure logging
logger = logging.getLogger(__name__)

def log_error(
    error: Exception,
    context: Optional[Dict[str, Any]] = None,
    level: int = logging.ERROR,
    include_traceback: bool = True,
    log_to_monitoring: bool = False,
) -> None:
    """
    """
        error_message += f" (Original error: {type(error.original_error).__name__}: {str(error.original_error)})"

    # Build log message
    message = f"{error_type}: {error_message}"

    # Add context if provided
    context_str = ""
    if context:
        context_str = " | Context: " + ", ".join(f"{k}={v}" for k, v in context.items())
        message += context_str

    # Log the error
    if include_traceback:
        logger.log(level, message, exc_info=True)
    else:
        logger.log(level, message)

    # Log to monitoring system if enabled
    if log_to_monitoring:
        try:

            pass
            from core.conductor.src.resilience.monitoring import get_monitoring_client

            monitoring_client = get_monitoring_client()

            monitoring_data = {
                "error_type": error_type,
                "error_message": error_message,
                "timestamp": datetime.now().isoformat(),
            }

            if context:
                monitoring_data.update(context)

            monitoring_client.report_error(monitoring_data)
        except Exception:

            pass
            logger.warning(f"Failed to log error to monitoring: {monitoring_error}")

def handle_error(
    error: Exception,
    context: Optional[Dict[str, Any]] = None,
    fallback_value: Optional[Any] = None,
    propagate_types: Optional[list] = None,
    always_log: bool = True,
    log_level: int = logging.ERROR,
    include_traceback: bool = True,
    log_to_monitoring: bool = False,
) -> Union[Any, Exception]:
    """
    """
    """
    """
                            logger.warning(f"Error in context provider: {context_error}")

                    # Add function name to context
                    if context is None:
                        context = {}
                    context["function"] = func.__name__

                    # Handle the error
                    return handle_error(
                        error=e,
                        context=context,
                        fallback_value=fallback_value,
                        propagate_types=propagate_types,
                        always_log=always_log,
                        log_level=log_level,
                        include_traceback=include_traceback,
                        log_to_monitoring=log_to_monitoring,
                    )

            return cast(F, async_wrapper)
        else:

            @functools.wraps(func)
            def sync_wrapper(*args: Any, **kwargs: Any) -> Any:
                try:

                    pass
                    return func(*args, **kwargs)
                except Exception:

                    pass
                    # Get context if a provider is specified
                    context = None
                    if context_provider:
                        try:

                            pass
                            context = context_provider(*args, **kwargs)
                        except Exception:

                            pass
                            logger.warning(f"Error in context provider: {context_error}")

                    # Add function name to context
                    if context is None:
                        context = {}
                    context["function"] = func.__name__

                    # Handle the error
                    return handle_error(
                        error=e,
                        context=context,
                        fallback_value=fallback_value,
                        propagate_types=propagate_types,
                        always_log=always_log,
                        log_level=log_level,
                        include_traceback=include_traceback,
                        log_to_monitoring=log_to_monitoring,
                    )

            return cast(F, sync_wrapper)

    return decorator

def retry(
    max_attempts: int = 3,
    delay_seconds: float = 1.0,
    backoff_factor: float = 2.0,
    retry_exceptions: Optional[list] = None,
    context_provider: Optional[Callable[..., Dict[str, Any]]] = None,
) -> Callable[[F], F]:
    """
    """
                        logger.warning(f"Error in context provider: {context_error}")

                # Add function name to context
                if context is None:
                    context = {}
                context["function"] = func.__name__

                for attempt in range(1, max_attempts + 1):
                    context["attempt"] = attempt

                    try:


                        pass
                        return await func(*args, **kwargs)
                    except Exception:

                        pass
                        last_exception = e

                        # Check if this except Exception:
     pass
                            # Don't retry - either wrong exception type or too many attempts
                            break

                        # Log the retry
                        logger.info(
                            f"Retrying {func.__name__} after error {type(e).__name__}: {str(e)}, "
                            f"attempt {attempt}/{max_attempts}, delay {current_delay}s"
                        )

                        # Wait before retrying
                        await asyncio.sleep(current_delay)

                        # Increase delay for next attempt
                        current_delay *= backoff_factor

                # If we get here, all retries failed
                if last_exception:
                    context["max_attempts"] = max_attempts
                    log_error(last_exception, context)
                    raise last_exception

                # This should never happen, but just in case
                raise RuntimeError("Retry logic failed, but no except Exception:
     pass
            @functools.wraps(func)
            def sync_wrapper(*args: Any, **kwargs: Any) -> Any:
                last_exception = None
                current_delay = delay_seconds

                # Get context if a provider is specified
                context = None
                if context_provider:
                    try:

                        pass
                        context = context_provider(*args, **kwargs)
                    except Exception:

                        pass
                        logger.warning(f"Error in context provider: {context_error}")

                # Add function name to context
                if context is None:
                    context = {}
                context["function"] = func.__name__

                for attempt in range(1, max_attempts + 1):
                    context["attempt"] = attempt

                    try:


                        pass
                        return func(*args, **kwargs)
                    except Exception:

                        pass
                        last_exception = e

                        # Check if this except Exception:
     pass
                            # Don't retry - either wrong exception type or too many attempts
                            break

                        # Log the retry
                        logger.info(
                            f"Retrying {func.__name__} after error {type(e).__name__}: {str(e)}, "
                            f"attempt {attempt}/{max_attempts}, delay {current_delay}s"
                        )

                        # Wait before retrying
                        import time

                        # TODO: Replace with asyncio.sleep() for async code
                        time.sleep(current_delay)

                        # Increase delay for next attempt
                        current_delay *= backoff_factor

                # If we get here, all retries failed
                if last_exception:
                    context["max_attempts"] = max_attempts
                    log_error(last_exception, context)
                    raise last_exception

                # This should never happen, but just in case
                raise RuntimeError("Retry logic failed, but no exception was raised")

            return cast(F, sync_wrapper)

    return decorator

def convert_exceptions(
    mapping: Dict[Type[Exception], Type[Exception]],
    context_provider: Optional[Callable[..., Dict[str, Any]]] = None,
) -> Callable[[F], F]:
    """
    """
                                    logger.warning(f"Error in context provider: {context_error}")

                            # Add function name to context
                            if context is None:
                                context = {}
                            context["function"] = func.__name__

                            # Create a new message incorporating the original except Exception:
     pass
                                new_exception = target_type(message, original_error=e)
                            else:
                                new_exception = target_type(message)

                            # Add the original traceback
                            new_exception.__traceback__ = e.__traceback__

                            raise new_exception

                    # If no conversion matches, re-raise the original except Exception:
     pass
            @functools.wraps(func)
            def sync_wrapper(*args: Any, **kwargs: Any) -> Any:
                try:

                    pass
                    return func(*args, **kwargs)
                except Exception:

                    pass
                    # Check if this except Exception:
     pass
                        if isinstance(e, source_type):
                            # Get context if a provider is specified
                            context = None
                            if context_provider:
                                try:

                                    pass
                                    context = context_provider(*args, **kwargs)
                                except Exception:

                                    pass
                                    logger.warning(f"Error in context provider: {context_error}")

                            # Add function name to context
                            if context is None:
                                context = {}
                            context["function"] = func.__name__

                            # Create a new message incorporating the original except Exception:
     pass
                                new_exception = target_type(message, original_error=e)
                            else:
                                new_exception = target_type(message)

                            # Add the original traceback
                            new_exception.__traceback__ = e.__traceback__

                            raise new_exception

                    # If no conversion matches, re-raise the original exception
                    raise

            return cast(F, sync_wrapper)

    return decorator
